Workbook

Sheet Start Here!
A1: PROJECT BONUS CALCULATOR — HOW TO USE | D1: PROJECTS TAB- DICTIONARY
D2: Variable | E2: Definition
A3: Purpose | D3: Project Name | E3: Name or identifier of the project.
A4: This tool provides a standardized way to evaluate project performance and calculate designer bonuses based on both qualitative and quantitative factors. | D4: Designer | E4: Designer responsible for the project.
D5: Customer Average | E5: Average customer survey score on a 1–5 scale; may be left blank if no survey is completed.
A6: STEP 1: Set Up (Admin Tab — Done Occasionally) | D6: Boss Q1 | E6: Score for client communication and relationship management (1–5).
A7: Navigate to the Admin tab | D7: Boss Q2 | E7: Score for design quality, attention to detail, and execution (1–5).
A8: Confirm or adjust: | D8: Boss Q3 | E8: Score for organization, timeline management, and project tracking (1–5).
A9: Max Bonus Amount | D9: Boss Q4 | E9: Score for problem solving and adaptability during the project (1–5).
A10: Weights (Subjective vs Objective) | D10: Boss Q5 | E10: Score for professionalism, accountability, and follow-through (1–5).
A11: Sub-category weights | D11: Mistakes | E11: Total number of mistakes recorded during the project.
A12: Objective weights | D12: Hours | E12: Total labor hours spent on the project.
A13: Mistake settings | D13: Profit | E13: Total profit generated from the project (in USD).
A14: Ensure all weight totals equal 1.00 | D14: Target Profit | E14: Expected or target profit for the project (in USD).
D15: Target Efficiency | E15: Expected profit per hour for the project (USD/hour).
A16: STEP 2: Add a New Project (Projects Tab) | D16: Boss Average | E16: Average of Boss Q1–Q5 scores (1–5 scale).
A17: Go to the Projects tab | D17: Boss Score | E17: Boss Average converted to a 0–1 scale.
A18: Add a new row at the bottom of the table | D18: Customer Score | E18: Customer Average converted to a 0–1 scale; blank if no survey is provided.
A19: Enter values in the blue cells only | D19: Mistake Rate | E19: Number of mistakes normalized to a standard time unit (per 50 hours).
D20: Mistake Score | E20: Score from 0–1 reflecting mistake performance, where fewer mistakes result in a higher score.
A21: STEP 3: Enter Project Inputs | D21: Profit Score | E21: Score from 0–1 comparing actual profit to target profit, capped at 1.
A22: Basic Info | D22: Efficiency Score | E22: Score from 0–1 comparing actual efficiency (profit per hour) to target efficiency, capped at 1.
A23: Project Name | D23: Sub Var | E23: Weighted subjective score combining customer, boss, and mistake performance.
A24: Designer | D24: Obj Var | E24: Weighted objective score combining profit and efficiency performance.
A25: Subjective Inputs | D25: Final Score | E25: Overall project score (0–1) based on weighted subjective and objective performance.
A26: Customer Score (1–5) (leave blank if no survey response) | D26: Bonus | E26: Recommended bonus amount calculated as Final Score multiplied by Max Bonus.
A27: Boss Evaluation (Q1–Q5) (use rubric sheet for guidance)
A28: Mistakes (total number of mistakes during the project) | D28: ADMIN TAB- DICTIONARY
A29: Objective Inputs | D29: Field | E29: Definition
A30: Hours (total labor hours) | D30: Max Bonus ($) | E30: Maximum bonus amount that can be awarded for a single project.
A31: Profit ($) (total project profit) | D31: Sub Var Weight | E31: Weight assigned to the subjective score in the final score calculation.
A32: Target Profit ($) (expected profit) | D32: Obj Var Weight | E32: Weight assigned to the objective score in the final score calculation.
A33: Target Efficiency ($/hr) (expected profit per hour) | D33: Customer Survey Weight | E33: Weight of the customer score within the subjective variable.
D34: Boss Evaluation Weight | E34: Weight of the boss evaluation within the subjective variable.
A35: STEP 4: Review Results (Automatic) | D35: Mistakes Weight | E35: Weight of the mistake score within the subjective variable.
A36: The spreadsheet will automatically calculate: | D36: Profit Weight | E36: Weight of the profit score within the objective variable.
A37: Subjective Score (sub_var) | D37: Efficiency Weight | E37: Weight of the efficiency score within the objective variable.
A38: Objective Score (obj_var) | D38: Normalization Hours | E38: Standard number of hours used to normalize mistakes (default is 50 hours).
A39: Final Score (0–1 scale) | D39: Max Mistake Rate (per Normalization Hours) | E39: Threshold for mistakes at which the mistake score reaches zero.
A40: Bonus Amount ($)
...

Sheet Admin
A1: Top Level Settings | B1: Values
A2: Max Bonus ($) | B2: 1000
A3: Sub Var Weight | B3: 0.6
A4: Obj Var Weight | B4: 0.4
A5: Total | B5: =SUM(B3:B4) -> 1
A7: Subjective Variable | B7: Weights
A8: Customer Survey | B8: 0.3
A9: Boss Evaluation | B9: 0.5
A10: Mistakes | B10: 0.2
A11: Total | B11: =SUM(B8:B10) -> 1
A13: Objective Variable | B13: Weights
A14: Profit | B14: 0.6
A15: Efficiency | B15: 0.4
A16: Total | B16: =SUM(B14:B15) -> 1
A18: Mistake Settings | B18: Values
A19: Normalization Hours | B19: 50
A20: Max Mistake Rate (per 50 hrs) | B20: 5

Sheet Boss Eval Questions
A1: Category | B1: Q1-5 | C1: Questions | E1: Score | F1: Definition
A2: Communication | B2: Q1 | C2: How effectively did the designer communicate with the client and maintain a positive relationship throughout the project? | E2: 1 | F2: Poor – Performance did not meet expectations and required significant correction or intervention.
A3: Design | B3: Q2 | C3: How strong was the overall design, attention to detail, and execution of the project? | E3: 2 | F3: Below Average – Performance occasionally met expectations but showed noticeable inconsistencies and required guidance.
A4: Organization | B4: Q3 | C4: How well did the designer stay organized, manage timelines, and keep the project on track? | E4: 3 | F4: Meets Expectations – Performance met expectations with reliable and consistent execution of responsibilities.
A5: Problem Solving | B5: Q4 | C5: How effectively did the designer handle challenges, changes, or unexpected issues during the project? | E5: 4 | F5: Above Average – Performance exceeded expectations with strong execution, initiative, and attention to detail.
A6: Professionalism | B6: Q5 | C6: How reliable and professional was the designer (ownership of work, follow-through, accountability)? | E6: 5 | F6: Excellent – Performance was exceptional, consistently exceeding expectations with outstanding ownership and execution.

Sheet Projects
A1: Project Name | B1: Designer | C1: Customer Average | D1: Boss Q1 | E1: Boss Q2 | F1: Boss Q3 | G1: Boss Q4 | H1: Boss Q5 | I1: Mistakes | J1: Hours | K1: Profit | L1: Target Profit | M1: Target Efficiency | N1: Boss Average | O1: Boss Score | P1: Customer Score | Q1: Mistake Rate | R1: Mistake Score | S1: Profit Score | T1: Efficiency Score | U1: Sub Var | V1: Obj Var | W1: Final Score | X1: Bonus
A2: Example Project 1 | C2: 2 | D2: 2 | E2: 3 | F2: 3 | G2: 5 | H2: 5 | I2: 5 | J2: 100 | K2: 4000 | L2: 5000 | M2: 100 | N2: =AVERAGE(Table2[[#This Row],[Boss Q1]],Table2[[#This Row],[Boss Q2]],Table2[[#This Row],[Boss Q3]],Table2[[#This Row],[Boss Q4]],Table2[[#This Row],[Boss Q5]]) -> 3.6 | O2: =(Table2[[#This Row],[Boss Average]]-1)/4 -> 0.65 | P2: =IF(Table2[[#This Row],[Customer Average]]="","", (Table2[[#This Row],[Customer Average]]-1)/4) -> 0.25 | Q2: =IF(Table2[[#This Row],[Hours]]<=0,"MISSING HOURS", (Table2[[#This Row],[Mistakes]]/Table2[[#This Row],[Hours]])*Admin!$B$19) -> 2.5 | R2: =IF(Table2[[#This Row],[Hours]]<=0,"MISSING HOURS", MAX(0,1-(Table2[[#This Row],[Mistake Rate]]/Admin!$B$20))) -> 0.5 | S2: =IF(Table2[[#This Row],[Target Profit]]<=0,"MISSING TARGET",MIN(1,Table2[[#This Row],[Profit]]/Table2[[#This Row],[Target Profit]])) -> 0.8 | T2: =IF(OR(Table2[[#This Row],[Hours]]<=0,Table2[[#This Row],[Target Efficiency]]<=0), "MISSING HOURS/TARGET", MIN(1,(Table2[[#This Row],[Profit]]/Table2[[#This Row],[Hours]])/Table2[[#This Row],[Target Efficiency]])) -> 0.4 | U2: =IF(Table2[[#This Row],[Customer Average]]="", ( (Table2[[#This Row],[Boss Score]]*Admin!$B$9)+(Table2[[#This Row],[Mistake Score]]*Admin!$B$10) )/(Admin!$B$9+Admin!$B$10), (Table2[[#This Row],[Customer Score]]*Admin!$B$8)+ (Table2[[#This Row],[Boss Score]]*Admin!$B$9)+ (Table2[[#This Row],[Mistake Score]]*Admin!$B$10) ) -> 0.5 | V2: =(Table2[[#This Row],[Profit Score]]*Admin!$B$14)+ (Table2[[#This Row],[Efficiency Score]]*Admin!$B$15) -> 0.64 | W2: =(Table2[[#This Row],[Sub Var]]*Admin!$B$3)+ (Table2[[#This Row],[Obj Var]]*Admin!$B$4) -> 0.556 | X2: =Table2[[#This Row],[Final Score]]*Admin!$B$2 -> 556
A3: Example Project 2 | C3: 5 | D3: 2 | E3: 4 | F3: 4 | G3: 3 | H3: 5 | I3: 3 | J3: 200 | K3: 10000 | L3: 12000 | M3: 300 | N3: =AVERAGE(Table2[[#This Row],[Boss Q1]],Table2[[#This Row],[Boss Q2]],Table2[[#This Row],[Boss Q3]],Table2[[#This Row],[Boss Q4]],Table2[[#This Row],[Boss Q5]]) -> 3.6 | O3: =(Table2[[#This Row],[Boss Average]]-1)/4 -> 0.65 | P3: =IF(Table2[[#This Row],[Customer Average]]="","", (Table2[[#This Row],[Customer Average]]-1)/4) -> 1 | Q3: =IF(Table2[[#This Row],[Hours]]<=0,"MISSING HOURS", (Table2[[#This Row],[Mistakes]]/Table2[[#This Row],[Hours]])*Admin!$B$19) -> 0.75 | R3: =IF(Table2[[#This Row],[Hours]]<=0,"MISSING HOURS", MAX(0,1-(Table2[[#This Row],[Mistake Rate]]/Admin!$B$20))) -> 0.85 | S3: =IF(Table2[[#This Row],[Target Profit]]<=0,"MISSING TARGET",MIN(1,Table2[[#This Row],[Profit]]/Table2[[#This Row],[Target Profit]])) -> 0.83333333 | T3: =IF(OR(Table2[[#This Row],[Hours]]<=0,Table2[[#This Row],[Target Efficiency]]<=0), "MISSING HOURS/TARGET", MIN(1,(Table2[[#This Row],[Profit]]/Table2[[#This Row],[Hours]])/Table2[[#This Row],[Target Efficiency]])) -> 0.16666667 | U3: =IF(Table2[[#This Row],[Customer Average]]="", ( (Table2[[#This Row],[Boss Score]]*Admin!$B$9)+(Table2[[#This Row],[Mistake Score]]*Admin!$B$10) )/(Admin!$B$9+Admin!$B$10), (Table2[[#This Row],[Customer Score]]*Admin!$B$8)+ (Table2[[#This Row],[Boss Score]]*Admin!$B$9)+ (Table2[[#This Row],[Mistake Score]]*Admin!$B$10) ) -> 0.795 | V3: =(Table2[[#This Row],[Profit Score]]*Admin!$B$14)+ (Table2[[#This Row],[Efficiency Score]]*Admin!$B$15) -> 0.56666667 | W3: =(Table2[[#This Row],[Sub Var]]*Admin!$B$3)+ (Table2[[#This Row],[Obj Var]]*Admin!$B$4) -> 0.70366667 | X3: =Table2[[#This Row],[Final Score]]*Admin!$B$2 -> 703.66667
